Workbook

Sheet 小倉ウルトラ追記
A1: No | B1: 競馬場 | C1: 距離 | D1: 芝/ダ | E1: 条件① | F1: 条件② | G1: 条件③ | H1: 3着内率(%) | I1: 単回収率(%) | J1: 複回収率(%) | K1: 推奨券種 | L1: 使用可否
A2: 1 | B2: 小倉 | C2: 芝1200 | D2: 芝 | E2: 前走京都芝1200内 | F2: 4角5番手以内 | G2: 3～8枠 | H2: 34.8 | I2: 79 | J2: 183 | K2: 複勝 | L2: ◎
A3: 2 | B3: 小倉 | C3: 芝1800 | D3: 芝 | E3: 父ダンジグ系 | F3: 関西馬 | G3: 1～12番 | H3: 37.3 | I3: 70 | J3: 243 | K3: 複勝 | L3: ◎
A4: 3 | B4: 小倉 | C4: 芝2000 | D4: 芝 | E4: 父ロベルト系 | F4: 1～7番 | G4: 16頭以下 | H4: 39.6 | I4: 154 | J4: 155 | K4: 単勝可 | L4: ◎
A5: 4 | B5: 小倉 | C5: ダ1000 | D5: ダ | E5: 最内枠 | F5: 56kg以下 | G5: 関西馬 | H5: 48.7 | I5: 51 | J5: 159 | K5: 複勝 | L5: ◎

Sheet 当日該当レース
A1: 日付 | B1: R | C1: 馬名 | D1: テンプレNo | E1: 単勝オッズ | F1: 複勝上限 | G1: 購入可否 | H1: 結果 | I1: 回収率(%) | J1: メモ | K1: コース | L1: 条件① | M1: 条件② | N1: 3着内率 | O1: 単回 | P1: 複回
K2: =IFERROR(VLOOKUP($D2,ウルトラ一覧!$A:$L,2,FALSE),"") | L2: =IFERROR(VLOOKUP($D2,ウルトラ一覧!$A:$L,3,FALSE),"") | M2: =IFERROR(VLOOKUP($D2,ウルトラ一覧!$A:$L,4,FALSE),"") | N2: =IFERROR(VLOOKUP($D2,ウルトラ一覧!$A:$L,8,FALSE),"") | O2: =IFERROR(VLOOKUP($D2,ウルトラ一覧!$A:$L,9,FALSE),"") | P2: =IFERROR(VLOOKUP($D2,ウルトラ一覧!$A:$L,10,FALSE),"")
K3: =IFERROR(VLOOKUP($D3,ウルトラ一覧!$A:$L,2,FALSE),"") | L3: =IFERROR(VLOOKUP($D3,ウルトラ一覧!$A:$L,3,FALSE),"") | M3: =IFERROR(VLOOKUP($D3,ウルトラ一覧!$A:$L,4,FALSE),"") | N3: =IFERROR(VLOOKUP($D3,ウルトラ一覧!$A:$L,8,FALSE),"") | O3: =IFERROR(VLOOKUP($D3,ウルトラ一覧!$A:$L,9,FALSE),"") | P3: =IFERROR(VLOOKUP($D3,ウルトラ一覧!$A:$L,10,FALSE),"")
K4: =IFERROR(VLOOKUP($D4,ウルトラ一覧!$A:$L,2,FALSE),"") | L4: =IFERROR(VLOOKUP($D4,ウルトラ一覧!$A:$L,3,FALSE),"") | M4: =IFERROR(VLOOKUP($D4,ウルトラ一覧!$A:$L,4,FALSE),"") | N4: =IFERROR(VLOOKUP($D4,ウルトラ一覧!$A:$L,8,FALSE),"") | O4: =IFERROR(VLOOKUP($D4,ウルトラ一覧!$A:$L,9,FALSE),"") | P4: =IFERROR(VLOOKUP($D4,ウルトラ一覧!$A:$L,10,FALSE),"")
K5: =IFERROR(VLOOKUP($D5,ウルトラ一覧!$A:$L,2,FALSE),"") | L5: =IFERROR(VLOOKUP($D5,ウルトラ一覧!$A:$L,3,FALSE),"") | M5: =IFERROR(VLOOKUP($D5,ウルトラ一覧!$A:$L,4,FALSE),"") | N5: =IFERROR(VLOOKUP($D5,ウルトラ一覧!$A:$L,8,FALSE),"") | O5: =IFERROR(VLOOKUP($D5,ウルトラ一覧!$A:$L,9,FALSE),"") | P5: =IFERROR(VLOOKUP($D5,ウルトラ一覧!$A:$L,10,FALSE),"")
K6: =IFERROR(VLOOKUP($D6,ウルトラ一覧!$A:$L,2,FALSE),"") | L6: =IFERROR(VLOOKUP($D6,ウルトラ一覧!$A:$L,3,FALSE),"") | M6: =IFERROR(VLOOKUP($D6,ウルトラ一覧!$A:$L,4,FALSE),"") | N6: =IFERROR(VLOOKUP($D6,ウルトラ一覧!$A:$L,8,FALSE),"") | O6: =IFERROR(VLOOKUP($D6,ウルトラ一覧!$A:$L,9,FALSE),"") | P6: =IFERROR(VLOOKUP($D6,ウルトラ一覧!$A:$L,10,FALSE),"")
K7: =IFERROR(VLOOKUP($D7,ウルトラ一覧!$A:$L,2,FALSE),"") | L7: =IFERROR(VLOOKUP($D7,ウルトラ一覧!$A:$L,3,FALSE),"") | M7: =IFERROR(VLOOKUP($D7,ウルトラ一覧!$A:$L,4,FALSE),"") | N7: =IFERROR(VLOOKUP($D7,ウルトラ一覧!$A:$L,8,FALSE),"") | O7: =IFERROR(VLOOKUP($D7,ウルトラ一覧!$A:$L,9,FALSE),"") | P7: =IFERROR(VLOOKUP($D7,ウルトラ一覧!$A:$L,10,FALSE),"")
K8: =IFERROR(VLOOKUP($D8,ウルトラ一覧!$A:$L,2,FALSE),"") | L8: =IFERROR(VLOOKUP($D8,ウルトラ一覧!$A:$L,3,FALSE),"") | M8: =IFERROR(VLOOKUP($D8,ウルトラ一覧!$A:$L,4,FALSE),"") | N8: =IFERROR(VLOOKUP($D8,ウルトラ一覧!$A:$L,8,FALSE),"") | O8: =IFERROR(VLOOKUP($D8,ウルトラ一覧!$A:$L,9,FALSE),"") | P8: =IFERROR(VLOOKUP($D8,ウルトラ一覧!$A:$L,10,FALSE),"")
K9: =IFERROR(VLOOKUP($D9,ウルトラ一覧!$A:$L,2,FALSE),"") | L9: =IFERROR(VLOOKUP($D9,ウルトラ一覧!$A:$L,3,FALSE),"") | M9: =IFERROR(VLOOKUP($D9,ウルトラ一覧!$A:$L,4,FALSE),"") | N9: =IFERROR(VLOOKUP($D9,ウルトラ一覧!$A:$L,8,FALSE),"") | O9: =IFERROR(VLOOKUP($D9,ウルトラ一覧!$A:$L,9,FALSE),"") | P9: =IFERROR(VLOOKUP($D9,ウルトラ一覧!$A:$L,10,FALSE),"")
K10: =IFERROR(VLOOKUP($D10,ウルトラ一覧!$A:$L,2,FALSE),"") | L10: =IFERROR(VLOOKUP($D10,ウルトラ一覧!$A:$L,3,FALSE),"") | M10: =IFERROR(VLOOKUP($D10,ウルトラ一覧!$A:$L,4,FALSE),"") | N10: =IFERROR(VLOOKUP($D10,ウルトラ一覧!$A:$L,8,FALSE),"") | O10: =IFERROR(VLOOKUP($D10,ウルトラ一覧!$A:$L,9,FALSE),"") | P10: =IFERROR(VLOOKUP($D10,ウルトラ一覧!$A:$L,10,FALSE),"")
K11: =IFERROR(VLOOKUP($D11,ウルトラ一覧!$A:$L,2,FALSE),"") | L11: =IFERROR(VLOOKUP($D11,ウルトラ一覧!$A:$L,3,FALSE),"") | M11: =IFERROR(VLOOKUP($D11,ウルトラ一覧!$A:$L,4,FALSE),"") | N11: =IFERROR(VLOOKUP($D11,ウルトラ一覧!$A:$L,8,FALSE),"") | O11: =IFERROR(VLOOKUP($D11,ウルトラ一覧!$A:$L,9,FALSE),"") | P11: =IFERROR(VLOOKUP($D11,ウルトラ一覧!$A:$L,10,FALSE),"")
K12: =IFERROR(VLOOKUP($D12,ウルトラ一覧!$A:$L,2,FALSE),"") | L12: =IFERROR(VLOOKUP($D12,ウルトラ一覧!$A:$L,3,FALSE),"") | M12: =IFERROR(VLOOKUP($D12,ウルトラ一覧!$A:$L,4,FALSE),"") | N12: =IFERROR(VLOOKUP($D12,ウルトラ一覧!$A:$L,8,FALSE),"") | O12: =IFERROR(VLOOKUP($D12,ウルトラ一覧!$A:$L,9,FALSE),"") | P12: =IFERROR(VLOOKUP($D12,ウルトラ一覧!$A:$L,10,FALSE),"")
K13: =IFERROR(VLOOKUP($D13,ウルトラ一覧!$A:$L,2,FALSE),"") | L13: =IFERROR(VLOOKUP($D13,ウルトラ一覧!$A:$L,3,FALSE),"") | M13: =IFERROR(VLOOKUP($D13,ウルトラ一覧!$A:$L,4,FALSE),"") | N13: =IFERROR(VLOOKUP($D13,ウルトラ一覧!$A:$L,8,FALSE),"") | O13: =IFERROR(VLOOKUP($D13,ウルトラ一覧!$A:$L,9,FALSE),"") | P13: =IFERROR(VLOOKUP($D13,ウルトラ一覧!$A:$L,10,FALSE),"")
... K500: =IFERROR(VLOOKUP($D500,ウルトラ一覧!$A:$L,2,FALSE),"") | L500: =IFERROR(VLOOKUP($D500,ウルトラ一覧!$A:$L,3,FALSE),"") | M500: =IFERROR(VLOOKUP($D500,ウルトラ一覧!$A:$L,4,FALSE),"") | N500: =IFERROR(VLOOKUP($D500,ウルトラ一覧!$A:$L,8,FALSE),"") | O500: =IFERROR(VLOOKUP($D500,ウルトラ一覧!$A:$L,9,FALSE),"") | P500: =IFERROR(VLOOKUP($D500,ウルトラ一覧!$A:$L,10,FALSE),"")

Sheet 騎手回収率データ
A1: 騎手名 | B1: 競馬場 | C1: 芝/ダ | D1: 良 | E1: 稍重 | F1: 重 | G1: 不良 | H1: 妙味度 | I1: 単回収率(%) | J1: 複回収率(%)

Sheet 実戦ログ
A1: 日付 | B1: 条件名 | C1: 購入額 | D1: 払戻額 | E1: 回収率(%) | F1: 反省・考察

Sheet 東京芝ウルトラ追記
A1: No | B1: コース | C1: 条件① | D1: 条件② | E1: 総成績(1-2-3-着外/総数) | F1: 勝率% | G1: 連対率% | H1: 3着内率% | I1: 単回収率% | J1: 複回収率% | K1: 推奨券種 | L1: 使用可否
A2: 001 | B2: 東京芝1400m | C2: 田辺裕信 | D2: 前走13着以内 | E2: 5-9-6-22/42 | F2: 11.9 | G2: 33.3 | H2: 47.6 | I2: 402 | J2: 170
A3: 002 | B3: 東京芝1400m | C3: 戸崎圭太 | D3: 中12週以内 | E3: 11-7-6-16/40 | F3: 27.5 | G3: 45 | H3: 60 | I3: 219 | J3: 160
A4: 003 | B4: 東京芝1400-1600m | C4: 父イスラボニータ | D4: 前走8着以内 | E4: 13-11-10-44/78 | F4: 16.7 | G4: 30.8 | H4: 43.6 | I4: 455 | J4: 154
A5: 004 | B5: 東京芝1600m | C5: 父モーリス | D5: 3歳以下 | E5: 11-15-14-60/100 | F5: 11 | G5: 26 | H5: 40 | I5: 218 | J5: 156
A6: 005 | B6: 東京芝1600m | C6: 父ロードカナロア | D6: 前走15頭立て以上 | E6: 6-9-12-41/68 | F6: 8.8 | G6: 22.1 | H6: 39.7 | I6: 19 | J6: 150
A7: 006 | B7: 東京芝1600m | C7: 吉田豊 | D7: 中8週以内 | E7: 4-7-13-17/41 | F7: 9.8 | G7: 26.8 | H7: 58.5 | I7: 74 | J7: 209
A8: 007 | B8: 東京芝1600m | C8: 前走中京芝1600-2000m | D8: 前走馬体重450kg以上 | E8: 7-6-10-38/61 | F8: 11.5 | G8: 21.3 | H8: 37.7 | I8: 217 | J8: 178
A9: 008 | B9: 東京芝1800-2000m | C9: 父キズナ | D9: 14頭立て以下+4歳以下 | E9: 13-13-11-39/76 | F9: 17.1 | G9: 34.2 | H9: 48.7 | I9: 69 | J9: 151
A10: 009 | B10: 東京芝2000m | C10: 北村宏司+1-7番 | D10: 出走16頭以下 | E10: 7-3-7-16/33 | F10: 21.2 | G10: 30.3 | H10: 51.5 | I10: 87 | J10: 200
A11: 010 | B11: 東京芝2400-3400m | C11: 父キングカメハメハ系+5-8枠 | D11: 13頭立て以下 | E11: 17-19-9-43/88 | F11: 19.3 | G11: 40.9 | H11: 51.1 | I11: 64 | J11: 164
A12: 011 | B12: 東京ダ1300m | C12: 前走上がり2位以内+470kg以上 | D12: 中7週以内 | E12: 9-7-7-36/59 | F12: 15.3 | G12: 27.1 | H12: 39 | I12: 221 | J12: 192
A13: 012 | B13: 東京ダ1400m | C13: 父ロードカナロア+4角5番手以内 | D13: 牡セン | E13: 9-12-5-15/41 | F13: 22 | G13: 51.2 | H13: 63.4 | I13: 152 | J13: 150
... A17: 016 | B17: 東京ダ2100m | C17: C.ルメール+父母父ミスプロ系以外 | D17: 牡セン | E17: 8-4-2-2/16 | F17: 50 | G17: 75 | H17: 87.5 | I17: 153 | J17: 164

Sheet 東京波乱度
A1: コース | B1: 集計R数 | C1: 平均頭数 | D1: 波乱指数 | E1: 波乱ランク
A2: 東京芝1400m | B2: 154R | C2: 14.9 | D2: +6 | E2: B
A3: 東京芝1600m | B3: 210R | C3: 14.3 | D3: -2 | E3: C
A4: 東京芝1800m | B4: 174R | C4: 13.7 | D4: -12 | E4: E
A5: 東京芝2000m | B5: 125R | C5: 12.4 | D5: -7 | E5: D
A6: 東京芝2300m | B6: 4R | C6: 12 | D6: -4 | E6: D
A7: 東京芝2400m | B7: 88R | C7: 13.4 | D7: -7 | E7: D
A8: 東京芝2500m | B8: 8R | C8: 15.8 | D8: -19 | E8: E
A9: 東京芝3400m | B9: 3R | C9: 14.6 | D9: +15 | E9: A
A10: 東京ダ1300m | B10: 69R | C10: 15.7 | D10: +6 | E10: B
A11: 東京ダ1400m | B11: 274R | C11: 15.6 | D11: -4 | E11: D
A12: 東京ダ1600m | B12: 339R | C12: 15.1 | D12: -4 | E12: D
A13: 東京ダ2100m | B13: 112R | C13: 15 | D13: -10 | E13: E

Sheet 京都ウルトラ追記
A1: No | B1: コース | C1: 条件① | D1: 条件② | E1: 総成績(1-2-3-着外/総数) | F1: 勝率% | G1: 連対率% | H1: 3着内率% | I1: 単回収率% | J1: 複回収率% | K1: 推奨券種 | L1: 使用可否
A2: 031 | B2: 京都芝1200m内 | C2: 前走4角1番手 | D2: 3歳以上 | E2: 12-9-5-44/70 | F2: 17.1 | G2: 30 | H2: 37.1 | I2: 141 | J2: 168
A3: 032 | B3: 京都芝1200-1400m内 | C3: 西村淳也+4歳以下 | E3: 2-4-10-17/33 | F3: 6.1 | G3: 18.2 | H3: 48.5 | I3: 21 | J3: 162
A4: 033 | B4: 京都芝1400m外 | C4: 前走4角1番手 | D4: 前走同距離以上+4歳以下 | E4: 7-5-6-25/43 | F4: 16.3 | G4: 27.9 | H4: 41.9 | I4: 215 | J4: 166
A5: 034 | B5: 京都芝1600-1800m | C5: 西村淳也 | D5: 14頭立て以下 | E5: 10-18-15-24/67 | F5: 14.9 | G5: 41.8 | H5: 64.2 | I5: 61 | J5: 153
A6: 035 | B6: 京都芝1600m外 | C6: 14-18番+450kg以上 | D6: 4歳以下 | E6: 8-5-7-39/59 | F6: 13.6 | G6: 22 | H6: 33.9 | I6: 343 | J6: 246
A7: 036 | B7: 京都芝1800m外 | C7: 父グラスワンダー系 | D7: 前走12着以内 | E7: 5-10-3-24/42 | F7: 11.9 | G7: 35.7 | H7: 42.9 | I7: 79 | J7: 277
A8: 037 | B8: 京都芝2200m外 | C8: 川田将雅+関西馬 | E8: 6-3-5-2/16 | F8: 37.5 | G8: 56.3 | H8: 87.5 | I8: 168 | J8: 190
A9: 038 | B9: 京都芝2400-3000m | C9: 前走上がり2位以内 | D9: 前走同頭数以上 | E9: 10-12-9-27/58 | F9: 17.2 | G9: 37.9 | H9: 53.4 | I9: 70 | J9: 171
A10: 039 | B10: 京都ダ1200m | C10: 父ドレフォン+前走4着以内 | D10: 中8週以内 | E10: 5-9-4-18/36 | F10: 13.9 | G10: 38.9 | H10: 50 | I10: 78 | J10: 175
A11: 040 | B11: 京都ダ1400m | C11: 坂井瑠星+1-9番+牡セン | E11: 11-5-5-13/34 | F11: 32.4 | G11: 47.1 | H11: 61.8 | I11: 158 | J11: 160
A12: 041 | B12: 京都ダ1400-1800m | C12: 高杉史麒+前走ダ | D12: 出走13頭以上 | E12: 9-10-6-45/70 | F12: 12.9 | G12: 27.1 | H12: 35.7 | I12: 176 | J12: 223
A13: 042 | B13: 京都ダ1800m | C13: 父シニスターミニスター+4歳以下 | E13: 25-18-7-63/113 | F13: 22.1 | G13: 38.1 | H13: 44.2 | I13: 148 | J13: 151
A14: 043 | B14: 京都ダ1800-1900m | C14: 鮫島克駿+480kg以上+前走8着以内 | E14: 3-9-13-28/53 | F14: 5.7 | G14: 22.6 | H14: 47.2 | I14: 29 | J14: 175
A15: 044 | B15: 京都ダ1800-1900m | C15: 田口貫太+4角2番手以内+450kg以上 | E15: 4-10-10-30/54 | F15: 7.4 | G15: 25.9 | H15: 44.4 | I15: 396 | J15: 218

Sheet 京都波乱度
A1: コース | B1: 集計R数 | C1: 平均頭数 | D1: 波乱指数 | E1: 波乱ランク
A2: 京都芝1200m内 | B2: 60R | C2: 15.3 | D2: +7 | E2: B
A3: 京都芝1400m内 | B3: 31R | C3: 16.2 | D3: ±0 | E3: C
A4: 京都芝1400m外 | B4: 62R | C4: 14.8 | D4: +10 | E4: A
A5: 京都芝1600m内 | B5: 80R | C5: 14.9 | D5: +1 | E5: C
A6: 京都芝1600m外 | B6: 60R | C6: 13.7 | D6: +2 | E6: C
A7: 京都芝1800m外 | B7: 110R | C7: 13.1 | D7: +12 | E7: A
A8: 京都芝2000m内 | B8: 106R | C8: 12.4 | D8: +6 | E8: B
A9: 京都芝2200m外 | B9: 43R | C9: 12.7 | D9: -8 | E9: D
A10: 京都芝2400m外 | B10: 36R | C10: 12.2 | D10: -1 | E10: C
A11: 京都芝3000m外 | B11: 5R | C11: 15.6 | D11: -24 | E11: E
A12: 京都芝3200m外 | B12: 3R | C12: 16.7 | D12: -21 | E12: E
A13: 京都ダ1200m | B13: 149R | C13: 15 | D13: +2 | E13: C
... A16: 京都ダ1900m | B16: 79R | C16: 13.5 | D16: +4 | E16: B

Sheet 阪神ウルトラ追記
A1: No | B1: コース | C1: 条件① | D1: 条件② | E1: 総成績(1-2-3-着外/総数) | F1: 勝率% | G1: 連対率% | H1: 3着内率% | I1: 単回収率% | J1: 複回収率% | K1: 推奨券種 | L1: 使用可否
A2: 045 | B2: 阪神芝1200m内 | C2: 父がストームキャット系種牡馬 | D2: 枠番が1～6枠 | E2: 3-8-7-17/35 | F2: 8.6 | G2: 31.4 | H2: 51.4 | I2: 126 | J2: 191
A3: 046 | B3: 阪神芝1400～1600m | C3: 父がハービンジャー | D3: 馬齢が4歳以下 | E3: 9-3-7-29/48 | F3: 18.8 | G3: 25 | H3: 39.6 | I3: 327 | J3: 209
A4: 047 | B4: 阪神芝1600～1800m | C4: 岩田望来騎手 | D4: 前走馬体重480kg以上 | E4: 9-11-5-20/45 | F4: 20 | G4: 44.4 | H4: 55.6 | I4: 97 | J4: 182
A5: 048 | B5: 阪神芝1800m外 | C5: 父がロベルト系種牡馬 | D5: 前走10着以内 | E5: 10-8-14-48/80 | F5: 12.5 | G5: 22.5 | H5: 40 | I5: 163 | J5: 162
A6: 052 | B6: 阪神ダ1400～1800m | C6: 父がシニスターミニスター | D6: 馬番3～16＋関西馬（栗東） | E6: 26-21-26-91/164 | F6: 15.9 | G6: 28.7 | H6: 44.5 | I6: 123 | J6: 151
A7: 053 | B7: 阪神ダ1400～1800m | C7: 父がドレフォン | D7: 前走上がり（3F順位）4位以内 | E7: 17-11-9-44/81 | F7: 21 | G7: 34.6 | H7: 45.7 | I7: 101 | J7: 161
A8: 054 | B8: 阪神ダ1800m | C8: 父がキズナ | D8: 3歳以下＋前走馬体重480kg以上 | E8: 11-14-8-17/50 | F8: 22 | G8: 50 | H8: 66 | I8: 137 | J8: 192
A9: 055 | B9: 阪神ダ1800～2000m | C9: 武豊騎手 | D9: 3歳以下＋性が牡・セ | E9: 7-8-3-9/27 | F9: 25.9 | G9: 55.6 | H9: 66.7 | I9: 153 | J9: 211
A10: 056 | B10: 阪神ダ1800～2000m | C10: M.デムーロ騎手 | D10: 3歳以下 | E10: 4-7-4-11/26 | F10: 15.4 | G10: 42.3 | H10: 57.7 | I10: 31 | J10: 206
A11: 057 | B11: 阪神ダ1800～2000m | C11: 横山典弘騎手 | D11: 馬番1～10＋9頭立て以上 | E11: 5-6-6-24/41 | F11: 12.2 | G11: 26.8 | H11: 41.5 | I11: 67 | J11: 155
A12: 058 | B12: 阪神ダ2000m | C12: 松山弘平騎手 | D12: 前走馬体重520kg未満 | E12: 5-6-4-8/23 | F12: 21.7 | G12: 47.8 | H12: 65.2 | I12: 96 | J12: 160

Sheet 阪神波乱度
A1: コース | B1: 集計R数 | C1: 平均頭数 | D1: 波乱指数 | E1: 波乱ランク
A2: 阪神芝1200m内 | B2: 57 | C2: 13.7 | D2: -1 | E2: C
A3: 阪神芝1400m内 | B3: 85 | C3: 14.9 | D3: -1 | E3: C
A4: 阪神芝1600m外 | B4: 137 | C4: 14.4 | D4: 1 | E4: C
A5: 阪神芝1800m外 | B5: 94 | C5: 13.2 | D5: 1 | E5: C
A6: 阪神芝2000m内 | B6: 111 | C6: 12.4 | D6: 5 | E6: B
A7: 阪神芝2200m内 | B7: 23 | C7: 13.8 | D7: -1 | E7: C
A8: 阪神芝2400m外 | B8: 45 | C8: 11.4 | D8: 5 | E8: B
A9: 阪神芝2600m外 | B9: 8 | C9: 11.2 | D9: -5 | E9: D
A10: 阪神芝3000m内 | B10: 8 | C10: 13.8 | D10: -6 | E10: D
A11: 阪神ダ1200m | B11: 159 | C11: 15.1 | D11: -4 | E11: D
A12: 阪神ダ1400m | B12: 192 | C12: 15 | D12: -7 | E12: D
A13: 阪神ダ1800m | B13: 314 | C13: 13 | D13: 4 | E13: B
A14: 阪神ダ2000m | B14: 49 | C14: 13.2 | D14: 14 | E14: A

Sheet ウルトラ一覧
A1: No | B1: コース | C1: 条件① | D1: 条件② | E1: 総成績(1-2-3-着外/総数) | F1: 勝率% | G1: 連対率% | H1: 3着内率% | I1: 単回収率% | J1: 複回収率% | K1: 推奨券種 | L1: 使用可否 | N1: No_一覧
A2: 1 | B2: 小倉芝芝1200m | C2: 前走京都芝1200内 | D2: 4角5番手以内＋3～8枠 | H2: 34.8 | I2: 79 | J2: 183 | K2: 複勝 | L2: ◎ | N2: 1
A3: 2 | B3: 小倉芝芝1800m | C3: 父ダンジグ系 | D3: 関西馬＋1～12番 | H3: 37.3 | I3: 70 | J3: 243 | K3: 複勝 | L3: ◎ | N3: 2
A4: 3 | B4: 小倉芝芝2000m | C4: 父ロベルト系 | D4: 1～7番＋16頭以下 | H4: 39.6 | I4: 154 | J4: 155 | K4: 単勝可 | L4: ◎ | N4: 3
A5: 4 | B5: 小倉ダダ1000m | C5: 最内枠 | D5: 56kg以下＋関西馬 | H5: 48.7 | I5: 51 | J5: 159 | K5: 複勝 | L5: ◎ | N5: 4
A6: 001 | B6: 東京芝1400m | C6: 田辺裕信 | D6: 前走13着以内 | E6: 5-9-6-22/42 | F6: 11.9 | G6: 33.3 | H6: 47.6 | I6: 402 | J6: 170 | N6: 001
A7: 002 | B7: 東京芝1400m | C7: 戸崎圭太 | D7: 中12週以内 | E7: 11-7-6-16/40 | F7: 27.5 | G7: 45 | H7: 60 | I7: 219 | J7: 160 | N7: 002
A8: 003 | B8: 東京芝1400-1600m | C8: 父イスラボニータ | D8: 前走8着以内 | E8: 13-11-10-44/78 | F8: 16.7 | G8: 30.8 | H8: 43.6 | I8: 455 | J8: 154 | N8: 003
A9: 004 | B9: 東京芝1600m | C9: 父モーリス | D9: 3歳以下 | E9: 11-15-14-60/100 | F9: 11 | G9: 26 | H9: 40 | I9: 218 | J9: 156 | N9: 004
A10: 005 | B10: 東京芝1600m | C10: 父ロードカナロア | D10: 前走15頭立て以上 | E10: 6-9-12-41/68 | F10: 8.8 | G10: 22.1 | H10: 39.7 | I10: 19 | J10: 150 | N10: 005
A11: 006 | B11: 東京芝1600m | C11: 吉田豊 | D11: 中8週以内 | E11: 4-7-13-17/41 | F11: 9.8 | G11: 26.8 | H11: 58.5 | I11: 74 | J11: 209 | N11: 006
A12: 007 | B12: 東京芝1600m | C12: 前走中京芝1600-2000m | D12: 前走馬体重450kg以上 | E12: 7-6-10-38/61 | F12: 11.5 | G12: 21.3 | H12: 37.7 | I12: 217 | J12: 178 | N12: 007
A13: 008 | B13: 東京芝1800-2000m | C13: 父キズナ | D13: 14頭立て以下+4歳以下 | E13: 13-13-11-39/76 | F13: 17.1 | G13: 34.2 | H13: 48.7 | I13: 69 | J13: 151 | N13: 008
A14: 009 | B14: 東京芝2000m | C14: 北村宏司+1-7番 | D14: 出走16頭以下 | E14: 7-3-7-16/33 | F14: 21.2 | G14: 30.3 | H14: 51.5 | I14: 87 | J14: 200 | N14: 009
A15: 010 | B15: 東京芝2400-3400m | C15: 父キングカメハメハ系+5-8枠 | D15: 13頭立て以下 | E15: 17-19-9-43/88 | F15: 19.3 | G15: 40.9 | H15: 51.1 | I15: 64 | J15: 164 | N15: 010
A16: 011 | B16: 東京ダ1300m | C16: 前走上がり2位以内+470kg以上 | D16: 中7週以内 | E16: 9-7-7-36/59 | F16: 15.3 | G16: 27.1 | H16: 39 | I16: 221 | J16: 192 | N16: 011
A17: 012 | B17: 東京ダ1400m | C17: 父ロードカナロア+4角5番手以内 | D17: 牡セン | E17: 9-12-5-15/41 | F17: 22 | G17: 51.2 | H17: 63.4 | I17: 152 | J17: 150 | N17: 012
... A22: 031 | B22: 京都芝1200m内 | C22: 前走4角1番手 | D22: 3歳以上 | E22: 12-9-5-44/70 | F22: 17.1 | G22: 30 | H22: 37.1 | I22: 141 | J22: 168 | N22: 031
A23: 032 | B23: 京都芝1200-1400m内 | C23: 西村淳也+4歳以下 | E23: 2-4-10-17/33 | F23: 6.1 | G23: 18.2 | H23: 48.5 | I23: 21 | J23: 162 | N23: 032
A24: 033 | B24: 京都芝1400m外 | C24: 前走4角1番手 | D24: 前走同距離以上+4歳以下 | E24: 7-5-6-25/43 | F24: 16.3 | G24: 27.9 | H24: 41.9 | I24: 215 | J24: 166 | N24: 033
A25: 034 | B25: 京都芝1600-1800m | C25: 西村淳也 | D25: 14頭立て以下 | E25: 10-18-15-24/67 | F25: 14.9 | G25: 41.8 | H25: 64.2 | I25: 61 | J25: 153 | N25: 034
A26: 035 | B26: 京都芝1600m外 | C26: 14-18番+450kg以上 | D26: 4歳以下 | E26: 8-5-7-39/59 | F26: 13.6 | G26: 22 | H26: 33.9 | I26: 343 | J26: 246 | N26: 035
A27: 036 | B27: 京都芝1800m外 | C27: 父グラスワンダー系 | D27: 前走12着以内 | E27: 5-10-3-24/42 | F27: 11.9 | G27: 35.7 | H27: 42.9 | I27: 79 | J27: 277 | N27: 036
A28: 037 | B28: 京都芝2200m外 | C28: 川田将雅+関西馬 | E28: 6-3-5-2/16 | F28: 37.5 | G28: 56.3 | H28: 87.5 | I28: 168 | J28: 190 | N28: 037
A29: 038 | B29: 京都芝2400-3000m | C29: 前走上がり2位以内 | D29: 前走同頭数以上 | E29: 10-12-9-27/58 | F29: 17.2 | G29: 37.9 | H29: 53.4 | I29: 70 | J29: 171 | N29: 038
A30: 039 | B30: 京都ダ1200m | C30: 父ドレフォン+前走4着以内 | D30: 中8週以内 | E30: 5-9-4-18/36 | F30: 13.9 | G30: 38.9 | H30: 50 | I30: 78 | J30: 175 | N30: 039
A31: 040 | B31: 京都ダ1400m | C31: 坂井瑠星+1-9番+牡セン | E31: 11-5-5-13/34 | F31: 32.4 | G31: 47.1 | H31: 61.8 | I31: 158 | J31: 160 | N31: 040
A32: 041 | B32: 京都ダ1400-1800m | C32: 高杉史麒+前走ダ | D32: 出走13頭以上 | E32: 9-10-6-45/70 | F32: 12.9 | G32: 27.1 | H32: 35.7 | I32: 176 | J32: 223 | N32: 041
A33: 042 | B33: 京都ダ1800m | C33: 父シニスターミニスター+4歳以下 | E33: 25-18-7-63/113 | F33: 22.1 | G33: 38.1 | H33: 44.2 | I33: 148 | J33: 151 | N33: 042
A34: 043 | B34: 京都ダ1800-1900m | C34: 鮫島克駿+480kg以上+前走8着以内 | E34: 3-9-13-28/53 | F34: 5.7 | G34: 22.6 | H34: 47.2 | I34: 29 | J34: 175 | N34: 043
A35: 044 | B35: 京都ダ1800-1900m | C35: 田口貫太+4角2番手以内+450kg以上 | E35: 4-10-10-30/54 | F35: 7.4 | G35: 25.9 | H35: 44.4 | I35: 396 | J35: 218 | N35: 044
A36: 045 | B36: 阪神芝1200m内 | C36: 父がストームキャット系種牡馬 | D36: 枠番が1～6枠 | E36: 3-8-7-17/35 | F36: 8.6 | G36: 31.4 | H36: 51.4 | I36: 126 | J36: 191 | N36: 045
A37: 046 | B37: 阪神芝1400～1600m | C37: 父がハービンジャー | D37: 馬齢が4歳以下 | E37: 9-3-7-29/48 | F37: 18.8 | G37: 25 | H37: 39.6 | I37: 327 | J37: 209 | N37: 046
A38: 047 | B38: 阪神芝1600～1800m | C38: 岩田望来騎手 | D38: 前走馬体重480kg以上 | E38: 9-11-5-20/45 | F38: 20 | G38: 44.4 | H38: 55.6 | I38: 97 | J38: 182 | N38: 047
A39: 048 | B39: 阪神芝1800m外 | C39: 父がロベルト系種牡馬 | D39: 前走10着以内 | E39: 10-8-14-48/80 | F39: 12.5 | G39: 22.5 | H39: 40 | I39: 163 | J39: 162 | N39: 048
A40: 052 | B40: 阪神ダ1400～1800m | C40: 父がシニスターミニスター | D40: 馬番3～16＋関西馬（栗東） | E40: 26-21-26-91/164 | F40: 15.9 | G40: 28.7 | H40: 44.5 | I40: 123 | J40: 151 | N40: 052
A41: 053 | B41: 阪神ダ1400～1800m | C41: 父がドレフォン | D41: 前走上がり（3F順位）4位以内 | E41: 17-11-9-44/81 | F41: 21 | G41: 34.6 | H41: 45.7 | I41: 101 | J41: 161 | N41: 053
A42: 054 | B42: 阪神ダ1800m | C42: 父がキズナ | D42: 3歳以下＋前走馬体重480kg以上 | E42: 11-14-8-17/50 | F42: 22 | G42: 50 | H42: 66 | I42: 137 | J42: 192 | N42: 054
A43: 055 | B43: 阪神ダ1800～2000m | C43: 武豊騎手 | D43: 3歳以下＋性が牡・セ | E43: 7-8-3-9/27 | F43: 25.9 | G43: 55.6 | H43: 66.7 | I43: 153 | J43: 211 | N43: 055
A44: 056 | B44: 阪神ダ1800～2000m | C44: M.デムーロ騎手 | D44: 3歳以下 | E44: 4-7-4-11/26 | F44: 15.4 | G44: 42.3 | H44: 57.7 | I44: 31 | J44: 206 | N44: 056
...
